Workbook

Sheet captureData
A1: record_number | B1: Band.Size | C1: Measurer | D1: Hora | E1: Dia | F1: Mes | G1: Ano | H1: Date collected | I1: Season | J1: Locality | K1: Habitat | L1: Red | M1: Scientific_Name | N1: Peso | O1: Nuevo.Recap | P1: Number/Code | Q1: band_num_est | R1: Cloaca | S1: Placa.de incubacion | T1: Grasa | U1: Muda.de.Cuerpo | V1: Mude.de.cola | W1: Muda.de.Plumas.del.Vuelo | X1: Degaste | Y1: Limite.de.Muda | Z1: Wing_Chord | AA1: Left.wing | AB1: Tail_Length | AC1: Codigo.de.Edad | AD1: Caracteristicas.para.Edad | AE1: Sex | AF1: Como.Sexo | AG1: Estado | AH1: Pluma | AI1: Sangre | AJ1: Escremento | AK1: L color band | AL1: R color band | AM1: HoraPhoto | AN1: Comments | AO1: Numero.de.Nota | AP1: Page.datasheet | AQ1: Bill_TotalCulmen | AR1: Bill_FromNostril | AS1: Bill_Width | AT1: Bill_Depth | AU1: Tarsus_Length | AV1: Kipp's_Distance | AW1: Gape_Width | AX1: CaliperMeasurer | AY1: Craneo | AZ1: Registrador | BA1: Feather.Verified | BB1: Blood.Inventory | BC1: Poop.Inventory | BD1: Latitude | BE1: Longitude | BF1: Elevation_masl | BG1: DistEdge_m | BH1: acc_m | BI1: Musculo | BJ1: Ala.der.plano | BK1: Tarso.diametro | BL1: total_head | BM1: Hallux | BN1: fotos | BO1: fotographo | BP1: ring_authority | BQ1: plumaje_juvenil | BR1: ff_moult_score | BS1: PP_moult_score | BT1: SS_moult_score | BU1: TT_moult_score | BV1: alulas | BW1: ppcovs | BX1: grcovs | BY1: medcovs | BZ1: lesscovs | CA1: underwing_covs | CB1: plumas_flanco | CC1: Desgaste old | CD1: Cloaca old | CE1: Placa.de.Incubacion old | CF1: Grasa old | CG1: Muda.de.Cuerpo old | CH1: Estacion old | CI1: Red old | CJ1: FLAG?
A2: 2878 | B2: 2 | C2: PFR | D2: 0.30138889 | E2: 26 | F2: 7 | G2: 2022 | H2: =DATE(G2,F2,E2) -> 44768 | I2: July_2022 | J2: Cuidad de la Paz (1.613482, 10.882453) | K2: P | L2: =IF(CI2="","", IF(AND(J2="P200W",CI2>=1,CI2<=20),CI2+200, IF(AND(J2="P0E",CI2>=1,CI2<=20),CI2+40, IF(AND(J2="P200E",CI2>=1,CI2<=20),CI2+240, IF(AND(J2="P400W",CI2>=1,CI2<=20),CI2+400, IF(AND(J2="P400E",CI2>=1,CI2<=20),CI2+440, IF(AND(J2="P600E",CI2>=1,CI2<=20),CI2+640, IF(AND(J2="P800E",CI2>=1,CI2<=20),CI2+840, IF(AND(J2="S200",CI2>=1,CI2<=20),CI2+200, IF(AND(J2="S100",CI2>=1,CI2<=20),CI2+700, IF(AND(J2="S1000",CI2>=1,CI2<=20),CI2+1000, IF(AND(J2="S400",CI2>=1,CI2<=20),CI2+400, IF(AND(OR(J2="University line",J2="S01"),CI2>=1,CI2<=45),CI2+500, CI2))))))))))))) -> 11 | M2: Criniger calurus | N2: 45 | O2: N | P2: E2536 | Q2: EGBI02536 | R2: 0 | S2: 0 | T2: 0 | U2: 0 | V2: NA | W2: A | X2: 2 | Y2: N | Z2: 107 | AA2: NA | AB2: 97 | AC2: FAJ | AD2: P | AE2: U | AF2: D | AG2: NA | AH2: S | AI2: S | AJ2: S | AN2: photo's on LLP's canon macro : "glamour shots" | AO2: 2 | AP2: 2 | AQ2: 23.6 | AR2: 13.3 | AS2: 7.1 | AT2: 7 | AU2: 24.3 | AV2: 16.1 | AW2: 13.6 | AX2: LLP | AZ2: NA | CC2: P | CD2: N | CE2: N | CF2: N | CG2: N | CH2: P14 | CI2: 11 | CJ2: =IF(COUNTIF(reviewFlags!A:C, A2) > 0, "FLAG", "") -> FLAG
A3: 2888 | B3: 1A | C3: LLP | D3: 0.31666667 | E3: 25 | F3: 7 | G3: 2022 | H3: =DATE(G3,F3,E3) -> 44767 | I3: July_2022 | J3: Cuidad de la Paz (1.613482, 10.882453) | K3: P | L3: =IF(CI3="","", IF(AND(J3="P200W",CI3>=1,CI3<=20),CI3+200, IF(AND(J3="P0E",CI3>=1,CI3<=20),CI3+40, IF(AND(J3="P200E",CI3>=1,CI3<=20),CI3+240, IF(AND(J3="P400W",CI3>=1,CI3<=20),CI3+400, IF(AND(J3="P400E",CI3>=1,CI3<=20),CI3+440, IF(AND(J3="P600E",CI3>=1,CI3<=20),CI3+640, IF(AND(J3="P800E",CI3>=1,CI3<=20),CI3+840, IF(AND(J3="S200",CI3>=1,CI3<=20),CI3+200, IF(AND(J3="S100",CI3>=1,CI3<=20),CI3+700, IF(AND(J3="S1000",CI3>=1,CI3<=20),CI3+1000, IF(AND(J3="S400",CI3>=1,CI3<=20),CI3+400, IF(AND(OR(J3="University line",J3="S01"),CI3>=1,CI3<=45),CI3+500, CI3))))))))))))) -> 1 | M3: Criniger chloronotus | N3: 42.5 | O3: N | P3: B10019 | Q3: XBI10019 | R3: 0 | S3: 0 | T3: 0 | U3: 0 | V3: NA | W3: N | X3: 0 | Y3: P | Z3: 106 | AA3: NA | AB3: 94 | AC3: FAJ | AD3: P | AE3: U | AF3: D | AG3: N | AH3: S | AI3: S | AJ3: S | AM3: 0.35833333 | AN3: Have the measurements to ID this bird | AO3: 1 | AP3: 2 | AQ3: 22.3 | AR3: 12.9 | AS3: 6.4 | AT3: 6.7 | AU3: 23.9 | AV3: 19.4 | AW3: 12.4 | AX3: LLP | AZ3: NA | CC3: M | CD3: N | CE3: N | CF3: N | CG3: N | CH3: P14 | CI3: 1 | CJ3: =IF(COUNTIF(reviewFlags!A:C, A3) > 0, "FLAG", "")
A4: 2889 | B4: 1B | C4: PFR | D4: 0.3625 | E4: 21 | F4: 7 | G4: 2022 | H4: =DATE(G4,F4,E4) -> 44763 | I4: July_2022 | J4: Cuidad de la Paz (1.613482, 10.882453) | K4: P | L4: =IF(CI4="","", IF(AND(J4="P200W",CI4>=1,CI4<=20),CI4+200, IF(AND(J4="P0E",CI4>=1,CI4<=20),CI4+40, IF(AND(J4="P200E",CI4>=1,CI4<=20),CI4+240, IF(AND(J4="P400W",CI4>=1,CI4<=20),CI4+400, IF(AND(J4="P400E",CI4>=1,CI4<=20),CI4+440, IF(AND(J4="P600E",CI4>=1,CI4<=20),CI4+640, IF(AND(J4="P800E",CI4>=1,CI4<=20),CI4+840, IF(AND(J4="S200",CI4>=1,CI4<=20),CI4+200, IF(AND(J4="S100",CI4>=1,CI4<=20),CI4+700, IF(AND(J4="S1000",CI4>=1,CI4<=20),CI4+1000, IF(AND(J4="S400",CI4>=1,CI4<=20),CI4+400, IF(AND(OR(J4="University line",J4="S01"),CI4>=1,CI4<=45),CI4+500, CI4))))))))))))) -> 10 | M4: Criniger calurus | N4: NA | O4: N | P4: B9903 | Q4: XBI9903 | R4: 0 | S4: 0 | T4: 0 | U4: 0 | V4: NA | W4: N | X4: 3 | Y4: N | Z4: 91 | AA4: NA | AB4: 87 | AC4: FAJ | AD4: P | AE4: U | AF4: D | AG4: NA | AH4: S | AI4: S | AJ4: N | AK4: B | AL4: # | AM4: 0.36111111 | AN4: 21.1 was the first tarsus measurement that LLP took; pretty sure shtat these caliper data are correct b/c this is the ony Criniger caloruson the datasheet | AO4: 8 | AP4: 1 | AR4: 10.4 | AS4: 6.7 | AT4: 5.3 | AU4: 21.8 | AV4: 15.6 | AW4: 14 | AX4: LLP | AZ4: NA | CC4: P | CD4: N | CE4: N | CF4: N | CG4: P | CH4: P10 | CI4: 10 | CJ4: =IF(COUNTIF(reviewFlags!A:C, A4) > 0, "FLAG", "")
A5: 2890 | B5: 1A | C5: PFR | D5: 0.31597222 | E5: 25 | F5: 7 | G5: 2022 | H5: =DATE(G5,F5,E5) -> 44767 | I5: July_2022 | J5: Cuidad de la Paz (1.613482, 10.882453) | K5: P | L5: =IF(CI5="","", IF(AND(J5="P200W",CI5>=1,CI5<=20),CI5+200, IF(AND(J5="P0E",CI5>=1,CI5<=20),CI5+40, IF(AND(J5="P200E",CI5>=1,CI5<=20),CI5+240, IF(AND(J5="P400W",CI5>=1,CI5<=20),CI5+400, IF(AND(J5="P400E",CI5>=1,CI5<=20),CI5+440, IF(AND(J5="P600E",CI5>=1,CI5<=20),CI5+640, IF(AND(J5="P800E",CI5>=1,CI5<=20),CI5+840, IF(AND(J5="S200",CI5>=1,CI5<=20),CI5+200, IF(AND(J5="S100",CI5>=1,CI5<=20),CI5+700, IF(AND(J5="S1000",CI5>=1,CI5<=20),CI5+1000, IF(AND(J5="S400",CI5>=1,CI5<=20),CI5+400, IF(AND(OR(J5="University line",J5="S01"),CI5>=1,CI5<=45),CI5+500, CI5))))))))))))) -> 19 | M5: Criniger chloronotus | N5: 43.4 | O5: N | P5: B10020 | Q5: XBI10020 | R5: 0 | S5: 2 | T5: 0 | U5: 0 | V5: NA | W5: N | X5: 1 | Y5: N | Z5: 100 | AA5: NA | AB5: 89 | AC5: FAJ | AD5: P | AE5: F | AF5: B | AG5: S | AH5: S | AI5: N | AJ5: N | AM5: 0.36180556 | AO5: 10 | AP5: 1 | AQ5: 20.3 | AR5: 12.1 | AS5: 6.4 | AT5: 7.1 | AU5: 23.4 | AV5: 13 | AW5: 13.6 | AX5: LLP | AZ5: NA | CC5: NA | CD5: NA | CE5: NA | CF5: NA | CG5: NA | CH5: P14 | CI5: 19 | CJ5: =IF(COUNTIF(reviewFlags!A:C, A5) > 0, "FLAG", "")
A6: 2897 | B6: 1B | C6: NWR | D6: 0.34652778 | E6: 28 | F6: 7 | G6: 2022 | H6: =DATE(G6,F6,E6) -> 44770 | I6: July_2022 | J6: Cuidad de la Paz (1.613482, 10.882453) | K6: P | L6: =IF(CI6="","", IF(AND(J6="P200W",CI6>=1,CI6<=20),CI6+200, IF(AND(J6="P0E",CI6>=1,CI6<=20),CI6+40, IF(AND(J6="P200E",CI6>=1,CI6<=20),CI6+240, IF(AND(J6="P400W",CI6>=1,CI6<=20),CI6+400, IF(AND(J6="P400E",CI6>=1,CI6<=20),CI6+440, IF(AND(J6="P600E",CI6>=1,CI6<=20),CI6+640, IF(AND(J6="P800E",CI6>=1,CI6<=20),CI6+840, IF(AND(J6="S200",CI6>=1,CI6<=20),CI6+200, IF(AND(J6="S100",CI6>=1,CI6<=20),CI6+700, IF(AND(J6="S1000",CI6>=1,CI6<=20),CI6+1000, IF(AND(J6="S400",CI6>=1,CI6<=20),CI6+400, IF(AND(OR(J6="University line",J6="S01"),CI6>=1,CI6<=45),CI6+500, CI6))))))))))))) -> 5 | M6: Eurillas latirostris | N6: 24.9 | O6: N | P6: B9931 | Q6: XBI9931 | R6: 0 | S6: 2 | T6: 0 | U6: 0 | V6: NA | W6: N | X6: 1 | Y6: N | Z6: 76 | AA6: NA | AB6: 74 | AC6: FAJ | AD6: P | AE6: F | AF6: B | AG6: N | AH6: S | AI6: S | AJ6: N | AM6: 0.40972222 | AO6: 11 | AP6: 1 | AQ6: 16.4 | AR6: 8.2 | AS6: 5.1 | AT6: 5.1 | AU6: 18 | AV6: 12.5 | AW6: 13.9 | AX6: LLP | AZ6: NA | CC6: M | CD6: N | CE6: N | CF6: N | CG6: P | CH6: P11 | CI6: 5 | CJ6: =IF(COUNTIF(reviewFlags!A:C, A6) > 0, "FLAG", "")
A7: 2908 | C7: PFR | D7: 0.46527778 | E7: 25 | F7: 7 | G7: 2022 | H7: =DATE(G7,F7,E7) -> 44767 | I7: July_2022 | J7: Cuidad de la Paz (1.613482, 10.882453) | K7: P | L7: =IF(CI7="","", IF(AND(J7="P200W",CI7>=1,CI7<=20),CI7+200, IF(AND(J7="P0E",CI7>=1,CI7<=20),CI7+40, IF(AND(J7="P200E",CI7>=1,CI7<=20),CI7+240, IF(AND(J7="P400W",CI7>=1,CI7<=20),CI7+400, IF(AND(J7="P400E",CI7>=1,CI7<=20),CI7+440, IF(AND(J7="P600E",CI7>=1,CI7<=20),CI7+640, IF(AND(J7="P800E",CI7>=1,CI7<=20),CI7+840, IF(AND(J7="S200",CI7>=1,CI7<=20),CI7+200, IF(AND(J7="S100",CI7>=1,CI7<=20),CI7+700, IF(AND(J7="S1000",CI7>=1,CI7<=20),CI7+1000, IF(AND(J7="S400",CI7>=1,CI7<=20),CI7+400, IF(AND(OR(J7="University line",J7="S01"),CI7>=1,CI7<=45),CI7+500, CI7))))))))))))) -> 6 | M7: Criniger ndussumensis | N7: 23.7 | O7: N | P7: B9920 | Q7: BI9920 | R7: 0 | S7: 2 | T7: 1 | U7: 0 | V7: NA | W7: N | X7: 2 | Y7: N | Z7: 80 | AA7: NA | AB7: 75 | AC7: FAJ | AD7: P | AE7: F | AF7: B | AG7: N | AH7: S | AI7: S | AJ7: N | AM7: 0.46666667 | AO7: 1 | AP7: 3 | AQ7: 19.1 | AR7: 10.4 | AS7: 4.5 | AT7: 5.1 | AU7: 20.3 | AV7: 10.3 | AW7: 11.6 | AX7: LLP | AZ7: NA | CC7: P | CD7: N | CE7: V | CF7: R | CG7: N | CH7: P14 | CI7: 6 | CJ7: =IF(COUNTIF(reviewFlags!A:C, A7) > 0, "FLAG", "")
A8: 2914 | B8: 1A | C8: PFR | D8: 0.37569444 | E8: 25 | F8: 7 | G8: 2022 | H8: =DATE(G8,F8,E8) -> 44767 | I8: July_2022 | J8: Cuidad de la Paz (1.613482, 10.882453) | K8: P | L8: =IF(CI8="","", IF(AND(J8="P200W",CI8>=1,CI8<=20),CI8+200, IF(AND(J8="P0E",CI8>=1,CI8<=20),CI8+40, IF(AND(J8="P200E",CI8>=1,CI8<=20),CI8+240, IF(AND(J8="P400W",CI8>=1,CI8<=20),CI8+400, IF(AND(J8="P400E",CI8>=1,CI8<=20),CI8+440, IF(AND(J8="P600E",CI8>=1,CI8<=20),CI8+640, IF(AND(J8="P800E",CI8>=1,CI8<=20),CI8+840, IF(AND(J8="S200",CI8>=1,CI8<=20),CI8+200, IF(AND(J8="S100",CI8>=1,CI8<=20),CI8+700, IF(AND(J8="S1000",CI8>=1,CI8<=20),CI8+1000, IF(AND(J8="S400",CI8>=1,CI8<=20),CI8+400, IF(AND(OR(J8="University line",J8="S01"),CI8>=1,CI8<=45),CI8+500, CI8))))))))))))) -> 20 | M8: Criniger chloronotus | N8: 41.8 | O8: N | P8: B10024 | Q8: XBI10024 | R8: 0 | S8: 0 | T8: 0 | U8: 0 | V8: NA | W8: N | X8: 4 | Y8: N | Z8: 101 | AA8: NA | AB8: 92 | AC8: FAJ | AD8: P | AE8: U | AF8: D | AG8: N | AH8: S | AI8: N | AJ8: N | AM8: 0.48819444 | AO8: 15 | AP8: 2 | AQ8: 23.4 | AR8: 13.4 | AS8: 6.4 | AT8: 6.6 | AU8: 25.2 | AV8: 21.7 | AW8: 13.4 | AX8: LLP | AZ8: NA | CC8: NA | CD8: NA | CE8: NA | CF8: NA | CG8: NA | CH8: P14 | CI8: 20 | CJ8: =IF(COUNTIF(reviewFlags!A:C, A8) > 0, "FLAG", "")
A9: 2926 | C9: PFR | D9: 0.51041667 | E9: 21 | F9: 7 | G9: 2022 | H9: =DATE(G9,F9,E9) -> 44763 | I9: July_2022 | J9: Cuidad de la Paz (1.613482, 10.882453) | K9: P | L9: =IF(CI9="","", IF(AND(J9="P200W",CI9>=1,CI9<=20),CI9+200, IF(AND(J9="P0E",CI9>=1,CI9<=20),CI9+40, IF(AND(J9="P200E",CI9>=1,CI9<=20),CI9+240, IF(AND(J9="P400W",CI9>=1,CI9<=20),CI9+400, IF(AND(J9="P400E",CI9>=1,CI9<=20),CI9+440, IF(AND(J9="P600E",CI9>=1,CI9<=20),CI9+640, IF(AND(J9="P800E",CI9>=1,CI9<=20),CI9+840, IF(AND(J9="S200",CI9>=1,CI9<=20),CI9+200, IF(AND(J9="S100",CI9>=1,CI9<=20),CI9+700, IF(AND(J9="S1000",CI9>=1,CI9<=20),CI9+1000, IF(AND(J9="S400",CI9>=1,CI9<=20),CI9+400, IF(AND(OR(J9="University line",J9="S01"),CI9>=1,CI9<=45),CI9+500, CI9))))))))))))) -> 15 | M9: Criniger ndussumensis | N9: 26.2 | O9: N | P9: B9910 | Q9: BI9910 | R9: 0 | S9: 0 | T9: 0 | U9: 0 | V9: NA | W9: N | X9: 2 | Y9: N | Z9: 87 | AA9: NA | AB9: 81 | AC9: FAJ | AD9: P | AE9: U | AF9: D | AG9: N | AH9: S | AI9: S | AJ9: N | AM9: 0.60555556 | AN9: see pics; apparent molt limit in underrwing covs. Symmetrical @p9-p7 | AO9: 12 | AP9: 2 | AR9: 11.8 | AS9: 4 | AT9: NA | AU9: 20.7 | AV9: 11.5 | AW9: 10.5 | AX9: LLP | AZ9: NA | CC9: P | CD9: N | CE9: N | CF9: N | CG9: N | CH9: P10 | CI9: 15 | CJ9: =IF(COUNTIF(reviewFlags!A:C, A9) > 0, "FLAG", "")
A10: 2987 | B10: 1B | C10: LLP | D10: 0.41666667 | E10: 21 | F10: 7 | G10: 2022 | H10: =DATE(G10,F10,E10) -> 44763 | I10: July_2022 | J10: Cuidad de la Paz (1.613482, 10.882453) | K10: P | L10: =IF(CI10="","", IF(AND(J10="P200W",CI10>=1,CI10<=20),CI10+200, IF(AND(J10="P0E",CI10>=1,CI10<=20),CI10+40, IF(AND(J10="P200E",CI10>=1,CI10<=20),CI10+240, IF(AND(J10="P400W",CI10>=1,CI10<=20),CI10+400, IF(AND(J10="P400E",CI10>=1,CI10<=20),CI10+440, IF(AND(J10="P600E",CI10>=1,CI10<=20),CI10+640, IF(AND(J10="P800E",CI10>=1,CI10<=20),CI10+840, IF(AND(J10="S200",CI10>=1,CI10<=20),CI10+200, IF(AND(J10="S100",CI10>=1,CI10<=20),CI10+700, IF(AND(J10="S1000",CI10>=1,CI10<=20),CI10+1000, IF(AND(J10="S400",CI10>=1,CI10<=20),CI10+400, IF(AND(OR(J10="University line",J10="S01"),CI10>=1,CI10<=45),CI10+500, CI10))))))))))))) -> 10 | M10: Eurillas latirostris | N10: 27.8 | O10: N | P10: B9906 | Q10: XBI9906 | R10: 0 | S10: 2 | T10: 1 | U10: 0 | V10: NA | W10: N | X10: 2 | Y10: N | Z10: 78 | AA10: NA | AB10: 70 | AC10: FAJ | AD10: P | AE10: F | AF10: B | AG10: N | AH10: S | AI10: S | AJ10: N | AL10: R | AO10: 5 | AP10: 2 | AR10: 9 | AS10: 5.2 | AT10: 5.1 | AU10: 19.6 | AV10: 11.6 | AW10: 12.3 | AX10: LLP | AZ10: NA | CC10: R | CD10: N | CE10: V | CF10: R | CG10: N | CH10: P10 | CI10: 10 | CJ10: =IF(COUNTIF(reviewFlags!A:C, A10) > 0, "FLAG", "")
A11: 2998 | B11: 1B | C11: LLP | D11: 0.43541667 | E11: 21 | F11: 7 | G11: 2022 | H11: =DATE(G11,F11,E11) -> 44763 | I11: July_2022 | J11: Cuidad de la Paz (1.613482, 10.882453) | K11: P | L11: =IF(CI11="","", IF(AND(J11="P200W",CI11>=1,CI11<=20),CI11+200, IF(AND(J11="P0E",CI11>=1,CI11<=20),CI11+40, IF(AND(J11="P200E",CI11>=1,CI11<=20),CI11+240, IF(AND(J11="P400W",CI11>=1,CI11<=20),CI11+400, IF(AND(J11="P400E",CI11>=1,CI11<=20),CI11+440, IF(AND(J11="P600E",CI11>=1,CI11<=20),CI11+640, IF(AND(J11="P800E",CI11>=1,CI11<=20),CI11+840, IF(AND(J11="S200",CI11>=1,CI11<=20),CI11+200, IF(AND(J11="S100",CI11>=1,CI11<=20),CI11+700, IF(AND(J11="S1000",CI11>=1,CI11<=20),CI11+1000, IF(AND(J11="S400",CI11>=1,CI11<=20),CI11+400, IF(AND(OR(J11="University line",J11="S01"),CI11>=1,CI11<=45),CI11+500, CI11))))))))))))) -> 19 | M11: Eurillas latirostris | N11: 24.9 | O11: N | P11: B9901 | Q11: XBI9901 | R11: 0 | S11: 2 | T11: 1 | U11: 0 | V11: NA | W11: N | X11: 1 | Y11: N | Z11: 80 | AA11: NA | AB11: 75 | AC11: FAJ | AD11: P | AE11: F | AF11: B | AG11: NA | AH11: S | AI11: S | AJ11: S | AO11: 22 | AP11: 1 | AR11: 9 | AS11: 4.4 | AT11: 5 | AU11: 20.2 | AV11: 11.5 | AW11: 12.4 | AX11: LLP | AZ11: NA | CH11: P10 | CI11: 19 | CJ11: =IF(COUNTIF(reviewFlags!A:C, A11) > 0, "FLAG", "")
A12: 3031 | B12: 1B | C12: PFR | D12: 0.52083333 | E12: 21 | F12: 7 | G12: 2022 | H12: =DATE(G12,F12,E12) -> 44763 | I12: July_2022 | J12: Cuidad de la Paz (1.613482, 10.882453) | K12: P | L12: =IF(CI12="","", IF(AND(J12="P200W",CI12>=1,CI12<=20),CI12+200, IF(AND(J12="P0E",CI12>=1,CI12<=20),CI12+40, IF(AND(J12="P200E",CI12>=1,CI12<=20),CI12+240, IF(AND(J12="P400W",CI12>=1,CI12<=20),CI12+400, IF(AND(J12="P400E",CI12>=1,CI12<=20),CI12+440, IF(AND(J12="P600E",CI12>=1,CI12<=20),CI12+640, IF(AND(J12="P800E",CI12>=1,CI12<=20),CI12+840, IF(AND(J12="S200",CI12>=1,CI12<=20),CI12+200, IF(AND(J12="S100",CI12>=1,CI12<=20),CI12+700, IF(AND(J12="S1000",CI12>=1,CI12<=20),CI12+1000, IF(AND(J12="S400",CI12>=1,CI12<=20),CI12+400, IF(AND(OR(J12="University line",J12="S01"),CI12>=1,CI12<=45),CI12+500, CI12))))))))))))) -> 19 | M12: Bleda notatus | N12: 31 | O12: N | P12: B9908 | Q12: BI9908 | R12: 0 | S12: 0 | T12: 1 | U12: 0 | V12: NA | W12: N | X12: 1 | Y12: N | Z12: 86 | AA12: NA | AB12: 77 | AC12: FAJ | AD12: P | AE12: U | AF12: D | AG12: N | AH12: S | AI12: S | AJ12: N | AO12: 8 | AP12: 2 | AR12: 11.3 | AS12: 4.7 | AT12: 5.8 | AU12: 24.6 | AV12: 11.5 | AW12: 12.2 | AX12: LLP | AZ12: NA | CC12: R | CD12: N | CE12: N | CF12: R | CG12: N | CH12: P10 | CI12: 19 | CJ12: =IF(COUNTIF(reviewFlags!A:C, A12) > 0, "FLAG", "")
A13: 3118 | C13: PFR | D13: 0.52638889 | E13: 21 | F13: 7 | G13: 2022 | H13: =DATE(G13,F13,E13) -> 44763 | I13: July_2022 | J13: Cuidad de la Paz (1.613482, 10.882453) | K13: P | L13: =IF(CI13="","", IF(AND(J13="P200W",CI13>=1,CI13<=20),CI13+200, IF(AND(J13="P0E",CI13>=1,CI13<=20),CI13+40, IF(AND(J13="P200E",CI13>=1,CI13<=20),CI13+240, IF(AND(J13="P400W",CI13>=1,CI13<=20),CI13+400, IF(AND(J13="P400E",CI13>=1,CI13<=20),CI13+440, IF(AND(J13="P600E",CI13>=1,CI13<=20),CI13+640, IF(AND(J13="P800E",CI13>=1,CI13<=20),CI13+840, IF(AND(J13="S200",CI13>=1,CI13<=20),CI13+200, IF(AND(J13="S100",CI13>=1,CI13<=20),CI13+700, IF(AND(J13="S1000",CI13>=1,CI13<=20),CI13+1000, IF(AND(J13="S400",CI13>=1,CI13<=20),CI13+400, IF(AND(OR(J13="University line",J13="S01"),CI13>=1,CI13<=45),CI13+500, CI13))))))))))))) -> 5 | M13: Eurillas latirostris | N13: 24.5 | O13: N | P13: B9907 | Q13: BI9907 | R13: 0 | S13: 0 | T13: 1 | U13: 0 | V13: NA | W13: S | X13: 2 | Y13: N | Z13: 72 | AA13: NA | AB13: 70 | AC13: FPF | AD13: M | AE13: U | AF13: D | AG13: N | AH13: S | AI13: N | AJ13: N | AN13: P3@60%; P4@80; P5@90; S9 reduced | AO13: 7 | AP13: 2 | AR13: 9.5 | AS13: 4.8 | AT13: 4.8 | AU13: 19.7 | AV13: 12.7 | AW13: 13.3 | AX13: LLP | AZ13: NA | CC13: P | CD13: N | CE13: N | CF13: R | CG13: N | CH13: P10 | CI13: 5 | CJ13: =IF(COUNTIF(reviewFlags!A:C, A13) > 0, "FLAG", "")
A14: 3893 | B14: 1 | C14: SAL | D14: 0.34027778 | E14: 20 | F14: 1 | G14: 2024 | H14: =DATE(G14,F14,E14) -> 45311 | I14: Winter_2024 | J14: Cuidad de la Paz (1.613482, 10.882453) | K14: P | L14: =IF(CI14="","", IF(AND(J14="P200W",CI14>=1,CI14<=20),CI14+200, IF(AND(J14="P0E",CI14>=1,CI14<=20),CI14+40, IF(AND(J14="P200E",CI14>=1,CI14<=20),CI14+240, IF(AND(J14="P400W",CI14>=1,CI14<=20),CI14+400, IF(AND(J14="P400E",CI14>=1,CI14<=20),CI14+440, IF(AND(J14="P600E",CI14>=1,CI14<=20),CI14+640, IF(AND(J14="P800E",CI14>=1,CI14<=20),CI14+840, IF(AND(J14="S200",CI14>=1,CI14<=20),CI14+200, IF(AND(J14="S100",CI14>=1,CI14<=20),CI14+700, IF(AND(J14="S1000",CI14>=1,CI14<=20),CI14+1000, IF(AND(J14="S400",CI14>=1,CI14<=20),CI14+400, IF(AND(OR(J14="University line",J14="S01"),CI14>=1,CI14<=45),CI14+500, CI14))))))))))))) -> 2 | M14: Eurillas curvirostris | N14: 24 | O14: N | P14: B10527 | Q14: BI10527 | R14: 0 | S14: 1 | T14: 0 | U14: 2 | W14: N | X14: 1 | Y14: M1, M2 | Z14: 74 | AB14: 65 | AC14: FCF | AD14: P | AE14: U | AF14: D | AG14: N | AH14: S | AI14: S | AJ14: S | AM14: 0.37430556 | AN14: 9:08 más fotos | AQ14: 16.1 | AR14: 9.1 | AS14: 3.8 | AT14: 4.2 | AU14: 24.3 | AV14: 7 | AW14: 11 | BD14: 1.618465 | BE14: 10.879474 | CC14: R | CD14: N | CE14: L | CF14: N | CG14: P | CH14: P641-660 | CI14: 2 | CJ14: =IF(COUNTIF(reviewFlags!A:C, A14) > 0, "FLAG", "")
A15: 3915 | B15: 1D | C15: SEM | D15: 0.36041667 | E15: 19 | F15: 1 | G15: 2024 | H15: =DATE(G15,F15,E15) -> 45310 | I15: Winter_2024 | J15: Cuidad de la Paz (1.613482, 10.882453) | K15: P | L15: =IF(CI15="","", IF(AND(J15="P200W",CI15>=1,CI15<=20),CI15+200, IF(AND(J15="P0E",CI15>=1,CI15<=20),CI15+40, IF(AND(J15="P200E",CI15>=1,CI15<=20),CI15+240, IF(AND(J15="P400W",CI15>=1,CI15<=20),CI15+400, IF(AND(J15="P400E",CI15>=1,CI15<=20),CI15+440, IF(AND(J15="P600E",CI15>=1,CI15<=20),CI15+640, IF(AND(J15="P800E",CI15>=1,CI15<=20),CI15+840, IF(AND(J15="S200",CI15>=1,CI15<=20),CI15+200, IF(AND(J15="S100",CI15>=1,CI15<=20),CI15+700, IF(AND(J15="S1000",CI15>=1,CI15<=20),CI15+1000, IF(AND(J15="S400",CI15>=1,CI15<=20),CI15+400, IF(AND(OR(J15="University line",J15="S01"),CI15>=1,CI15<=45),CI15+500, CI15))))))))))))) -> 2 | M15: Bleda notatus | N15: 40.4 | O15: N | P15: B10313 | Q15: BI10313 | R15: 0 | S15: 0 | T15: 0 | U15: 0 | W15: N | X15: 0 | Y15: N | Z15: 97 | AB15: 92 | AC15: FAJ | AD15: P | AE15: U | AF15: D | AG15: N | AH15: S | AI15: S | AJ15: N | AM15: 0.39166667 | AQ15: 15.9 | AR15: 8.2 | AS15: 4.4 | AT15: 3.5 | AU15: 23.9 | AV15: 8.1 | AW15: 11.4 | BD15: 1.620251 | BE15: 10.880505 | CC15: N | CD15: N | CE15: N | CF15: N | CG15: N | CH15: P841-860 | CI15: 2 | CJ15: =IF(COUNTIF(reviewFlags!A:C, A15) > 0, "FLAG", "")
A16: 4025 | B16: 1B | C16: PAN | D16: 0.4 | E16: 16 | F16: 1 | G16: 2024 | H16: =DATE(G16,F16,E16) -> 45307 | I16: Winter_2024 | J16: Cuidad de la Paz (1.613482, 10.882453) | K16: P | L16: =IF(CI16="","", IF(AND(J16="P200W",CI16>=1,CI16<=20),CI16+200, IF(AND(J16="P0E",CI16>=1,CI16<=20),CI16+40, IF(AND(J16="P200E",CI16>=1,CI16<=20),CI16+240, IF(AND(J16="P400W",CI16>=1,CI16<=20),CI16+400, IF(AND(J16="P400E",CI16>=1,CI16<=20),CI16+440, IF(AND(J16="P600E",CI16>=1,CI16<=20),CI16+640, IF(AND(J16="P800E",CI16>=1,CI16<=20),CI16+840, IF(AND(J16="S200",CI16>=1,CI16<=20),CI16+200, IF(AND(J16="S100",CI16>=1,CI16<=20),CI16+700, IF(AND(J16="S1000",CI16>=1,CI16<=20),CI16+1000, IF(AND(J16="S400",CI16>=1,CI16<=20),CI16+400, IF(AND(OR(J16="University line",J16="S01"),CI16>=1,CI16<=45),CI16+500, CI16))))))))))))) -> 4 | M16: Phyllastrephus xavieri | N16: 26 | O16: N | P16: B11605 | Q16: BI11605 | R16: 0 | S16: 0 | T16: 0 | U16: 0 | W16: N | X16: 0 | Y16: N | Z16: 76 | AB16: 72 | AC16: FAJ | AD16: P | AE16: U | AF16: D | AG16: N | AH16: S | AI16: S | AJ16: S | AM16: 0.46319444 | AQ16: 20.9 | AR16: 12.8 | AS16: 5 | AT16: 5.1 | AU16: 21.2 | AV16: 9.3 | AW16: 12 | BD16: 1.615149 | BE16: 10.883472 | CC16: N | CD16: N | CE16: N | CF16: N | CG16: N | CH16: P241-260 | CI16: 4 | CJ16: =IF(COUNTIF(reviewFlags!A:C, A16) > 0, "FLAG", "")
A17: 4050 | B17: 1B | C17: SEM | D17: 0.44444444 | E17: 19 | F17: 1 | G17: 2024 | H17: =DATE(G17,F17,E17) -> 45310 | I17: Winter_2024 | J17: Cuidad de la Paz (1.613482, 10.882453) | K17: P | L17: =IF(CI17="","", IF(AND(J17="P200W",CI17>=1,CI17<=20),CI17+200, IF(AND(J17="P0E",CI17>=1,CI17<=20),CI17+40, IF(AND(J17="P200E",CI17>=1,CI17<=20),CI17+240, IF(AND(J17="P400W",CI17>=1,CI17<=20),CI17+400, IF(AND(J17="P400E",CI17>=1,CI17<=20),CI17+440, IF(AND(J17="P600E",CI17>=1,CI17<=20),CI17+640, IF(AND(J17="P800E",CI17>=1,CI17<=20),CI17+840, IF(AND(J17="S200",CI17>=1,CI17<=20),CI17+200, IF(AND(J17="S100",CI17>=1,CI17<=20),CI17+700, IF(AND(J17="S1000",CI17>=1,CI17<=20),CI17+1000, IF(AND(J17="S400",CI17>=1,CI17<=20),CI17+400, IF(AND(OR(J17="University line",J17="S01"),CI17>=1,CI17<=45),CI17+500, CI17))))))))))))) -> 6 | M17: Criniger calurus | N17: 25.4 | O17: N | P17: B11621 | Q17: BI11621 | R17: 0 | S17: 0 | T17: 0 | U17: 1 | W17: N | X17: 0 | Y17: N | Z17: 96 | AB17: 76 | AC17: FAJ | AD17: P | AE17: U | AF17: D | AG17: N | AH17: S | AI17: S | AJ17: S | AM17: 0.49097222 | AN17: Inner claw = 7.2 | AQ17: 18.8 | AR17: 11.9 | AS17: 7.8 | AT17: 5 | AU17: 21.4 | AV17: 15.7 | AW17: 12.1 | BD17: 1.619982 | BE17: 10.88172 | CC17: N | CD17: N | CE17: N | CF17: N | CG17: R | CH17: P841-860 | CI17: 6 | CJ17: =IF(COUNTIF(reviewFlags!A:C, A17) > 0, "FLAG", "")
A18: 4107 | B18: 1B | C18: SEM | D18: 0.52847222 | E18: 16 | F18: 1 | G18: 2024 | H18: =DATE(G18,F18,E18) -> 45307 | I18: Winter_2024 | J18: Cuidad de la Paz (1.613482, 10.882453) | K18: P | L18: =IF(CI18="","", IF(AND(J18="P200W",CI18>=1,CI18<=20),CI18+200, IF(AND(J18="P0E",CI18>=1,CI18<=20),CI18+40, IF(AND(J18="P200E",CI18>=1,CI18<=20),CI18+240, IF(AND(J18="P400W",CI18>=1,CI18<=20),CI18+400, IF(AND(J18="P400E",CI18>=1,CI18<=20),CI18+440, IF(AND(J18="P600E",CI18>=1,CI18<=20),CI18+640, IF(AND(J18="P800E",CI18>=1,CI18<=20),CI18+840, IF(AND(J18="S200",CI18>=1,CI18<=20),CI18+200, IF(AND(J18="S100",CI18>=1,CI18<=20),CI18+700, IF(AND(J18="S1000",CI18>=1,CI18<=20),CI18+1000, IF(AND(J18="S400",CI18>=1,CI18<=20),CI18+400, IF(AND(OR(J18="University line",J18="S01"),CI18>=1,CI18<=45),CI18+500, CI18))))))))))))) -> 2 | M18: Phyllastrephus xavieri | N18: 22 | O18: N | P18: B11609 | Q18: BI11609 | R18: 0 | S18: 4 | T18: 0 | U18: 0 | W18: N | X18: 3 | Y18: N | Z18: 78 | AB18: 69 | AC18: FAJ | AD18: P | AE18: U | AF18: D | AG18: N | AH18: S | AI18: S | AJ18: S | AM18: 0.55138889 | AQ18: 17.8 | AR18: 11.5 | AS18: 5.2 | AT18: 4.8 | AU18: 20 | AV18: 11.9 | AW18: 11.4 | BD18: 1.6134822 | BE18: 10.882453 | CC18: M | CD18: N | CE18: A | CF18: N | CG18: N | CH18: P41-60 | CI18: 2 | CJ18: =IF(COUNTIF(reviewFlags!A:C, A18) > 0, "FLAG", "")
A19: 4112 | B19: 1B | C19: SEM | D19: 0.52430556 | E19: 16 | F19: 1 | G19: 2024 | H19: =DATE(G19,F19,E19) -> 45307 | I19: Winter_2024 | J19: Cuidad de la Paz (1.613482, 10.882453) | K19: P | L19: =IF(CI19="","", IF(AND(J19="P200W",CI19>=1,CI19<=20),CI19+200, IF(AND(J19="P0E",CI19>=1,CI19<=20),CI19+40, IF(AND(J19="P200E",CI19>=1,CI19<=20),CI19+240, IF(AND(J19="P400W",CI19>=1,CI19<=20),CI19+400, IF(AND(J19="P400E",CI19>=1,CI19<=20),CI19+440, IF(AND(J19="P600E",CI19>=1,CI19<=20),CI19+640, IF(AND(J19="P800E",CI19>=1,CI19<=20),CI19+840, IF(AND(J19="S200",CI19>=1,CI19<=20),CI19+200, IF(AND(J19="S100",CI19>=1,CI19<=20),CI19+700, IF(AND(J19="S1000",CI19>=1,CI19<=20),CI19+1000, IF(AND(J19="S400",CI19>=1,CI19<=20),CI19+400, IF(AND(OR(J19="University line",J19="S01"),CI19>=1,CI19<=45),CI19+500, CI19))))))))))))) -> 2 | M19: Criniger calurus | N19: 28 | O19: N | P19: B11610 | Q19: BI11610 | R19: 0 | S19: 0 | T19: 1 | U19: 0 | W19: N | X19: 1 | Y19: N | Z19: 82 | AB19: 75 | AC19: FAJ | AD19: P | AE19: U | AF19: D | AG19: N | AH19: S | AI19: S | AJ19: N | AM19: 0.55625 | AQ19: 19.5 | AR19: 11.5 | AS19: 5.6 | AT19: 5.6 | AU19: 20.9 | AV19: 10.9 | AW19: 12 | BD19: 1.6151235 | BE19: 10.881962 | CC19: R | CD19: N | CE19: N | CF19: R | CG19: N | CH19: P241-260 | CI19: 2 | CJ19: =IF(COUNTIF(reviewFlags!A:C, A19) > 0, "FLAG", "")
A20: 4116 | B20: 1A | C20: BRA | D20: 0.48611111 | E20: 12 | F20: 1 | G20: 2024 | H20: =DATE(G20,F20,E20) -> 45303 | I20: Winter_2024 | J20: Cuidad de la Paz (1.613482, 10.882453) | K20: P | L20: =IF(CI20="","", IF(AND(J20="P200W",CI20>=1,CI20<=20),CI20+200, IF(AND(J20="P0E",CI20>=1,CI20<=20),CI20+40, IF(AND(J20="P200E",CI20>=1,CI20<=20),CI20+240, IF(AND(J20="P400W",CI20>=1,CI20<=20),CI20+400, IF(AND(J20="P400E",CI20>=1,CI20<=20),CI20+440, IF(AND(J20="P600E",CI20>=1,CI20<=20),CI20+640, IF(AND(J20="P800E",CI20>=1,CI20<=20),CI20+840, IF(AND(J20="S200",CI20>=1,CI20<=20),CI20+200, IF(AND(J20="S100",CI20>=1,CI20<=20),CI20+700, IF(AND(J20="S1000",CI20>=1,CI20<=20),CI20+1000, IF(AND(J20="S400",CI20>=1,CI20<=20),CI20+400, IF(AND(OR(J20="University line",J20="S01"),CI20>=1,CI20<=45),CI20+500, CI20))))))))))))) -> 3 | M20: Phyllastrephus xavieri | N20: NA | O20: N | P20: B10157 | Q20: [1A]BI10157 | R20: 0 | S20: 0 | T20: 1 | U20: 0 | V20: NA | W20: N | X20: 1 | Y20: N | Z20: 81 | AA20: NA | AB20: 70 | AC20: FAJ | AD20: P | AE20: U | AF20: D | AG20: N | AH20: S | AI20: S | AJ20: S | AM20: 0.5625 | AN20: BIG HEAVY BEAK | AO20: 20 | AQ20: 20.2 | AR20: 12.3 | AS20: 4.2 | AT20: 5.3 | AU20: 21.9 | AV20: 8.7 | AW20: 3.3 | BD20: 1.61322 | BE20: 10.87854 | CC20: R | CD20: N | CE20: N | CF20: R | CG20: N | CH20: P1-20 | CI20: 3 | CJ20: =IF(COUNTIF(reviewFlags!A:C, A20) > 0, "FLAG", "")
A21: 4120 | B21: 1B | C21: BRA | D21: 0.52916667 | E21: 22 | F21: 1 | G21: 2024 | H21: =DATE(G21,F21,E21) -> 45313 | I21: Winter_2024 | J21: Cuidad de la Paz (1.613482, 10.882453) | K21: S | L21: =IF(CI21="","", IF(AND(J21="P200W",CI21>=1,CI21<=20),CI21+200, IF(AND(J21="P0E",CI21>=1,CI21<=20),CI21+40, IF(AND(J21="P200E",CI21>=1,CI21<=20),CI21+240, IF(AND(J21="P400W",CI21>=1,CI21<=20),CI21+400, IF(AND(J21="P400E",CI21>=1,CI21<=20),CI21+440, IF(AND(J21="P600E",CI21>=1,CI21<=20),CI21+640, IF(AND(J21="P800E",CI21>=1,CI21<=20),CI21+840, IF(AND(J21="S200",CI21>=1,CI21<=20),CI21+200, IF(AND(J21="S100",CI21>=1,CI21<=20),CI21+700, IF(AND(J21="S1000",CI21>=1,CI21<=20),CI21+1000, IF(AND(J21="S400",CI21>=1,CI21<=20),CI21+400, IF(AND(OR(J21="University line",J21="S01"),CI21>=1,CI21<=45),CI21+500, CI21))))))))))))) -> 2 | M21: Eurillas virens | N21: 26 | O21: N | P21: B11644 | Q21: BI11644 | R21: 0 | S21: 0 | T21: 2 | U21: 1 | V21: NA | W21: N | X21: 1 | Y21: N | Z21: 76 | AA21: NA | AB21: 71 | AC21: FAJ | AD21: P | AE21: U | AF21: D | AG21: N | AH21: S | AI21: S | AJ21: S | AM21: 0.56736111 | AN21: SUSPENDED MOLT,S4-6V | AQ21: 1.5 | AR21: 8.8 | AS21: 5.2 | AT21: 4.9 | AU21: 20.8 | AW21: 12.1 | BD21: 1.616319 | BE21: 10.864297 | CC21: R | CD21: N | CE21: N | CF21: P | CG21: R | CH21: S1001-1040 | CI21: 2 | CJ21: =IF(COUNTIF(reviewFlags!A:C, A21) > 0, "FLAG", "")
A22: 4122 | B22: 1D | C22: BRA | D22: 0.52569444 | E22: 16 | F22: 1 | G22: 2024 | H22: =DATE(G22,F22,E22) -> 45307 | I22: Winter_2024 | J22: Cuidad de la Paz (1.613482, 10.882453) | K22: P | L22: =IF(CI22="","", IF(AND(J22="P200W",CI22>=1,CI22<=20),CI22+200, IF(AND(J22="P0E",CI22>=1,CI22<=20),CI22+40, IF(AND(J22="P200E",CI22>=1,CI22<=20),CI22+240, IF(AND(J22="P400W",CI22>=1,CI22<=20),CI22+400, IF(AND(J22="P400E",CI22>=1,CI22<=20),CI22+440, IF(AND(J22="P600E",CI22>=1,CI22<=20),CI22+640, IF(AND(J22="P800E",CI22>=1,CI22<=20),CI22+840, IF(AND(J22="S200",CI22>=1,CI22<=20),CI22+200, IF(AND(J22="S100",CI22>=1,CI22<=20),CI22+700, IF(AND(J22="S1000",CI22>=1,CI22<=20),CI22+1000, IF(AND(J22="S400",CI22>=1,CI22<=20),CI22+400, IF(AND(OR(J22="University line",J22="S01"),CI22>=1,CI22<=45),CI22+500, CI22))))))))))))) -> 29 | M22: Criniger calurus | N22: 29 | O22: N | P22: B10309 | Q22: BI10309 | R22: 0 | S22: 1 | T22: 0 | U22: 0 | W22: N | X22: 1 | Y22: N | Z22: 86 | AB22: 81 | AC22: FAJ | AD22: P | AE22: U | AF22: D | AG22: N | AH22: S | AI22: S | AJ22: S | AM22: 0.57569444 | AN22: P1-3=N P4G=40% P5-10=V | AQ22: 19.6 | AR22: 12.3 | AS22: 6.1 | AT22: 6.3 | AU22: 20.1 | AV22: 7.6 | AW22: 13.1 | BD22: 1.6150898 | BE22: 10.881696 | CC22: R | CD22: N | CE22: L | CF22: N | CG22: N | CH22: P241-260 | CI22: 29 | CJ22: =IF(COUNTIF(reviewFlags!A:C, A22) > 0, "FLAG", "")
A23: 4125 | B23: 1A | C23: SAL | D23: 0.52083333 | E23: 13 | F23: 1 | G23: 2024 | H23: =DATE(G23,F23,E23) -> 45304 | I23: Winter_2024 | J23: Cuidad de la Paz (1.613482, 10.882453) | K23: P | L23: =IF(CI23="","", IF(AND(J23="P200W",CI23>=1,CI23<=20),CI23+200, IF(AND(J23="P0E",CI23>=1,CI23<=20),CI23+40, IF(AND(J23="P200E",CI23>=1,CI23<=20),CI23+240, IF(AND(J23="P400W",CI23>=1,CI23<=20),CI23+400, IF(AND(J23="P400E",CI23>=1,CI23<=20),CI23+440, IF(AND(J23="P600E",CI23>=1,CI23<=20),CI23+640, IF(AND(J23="P800E",CI23>=1,CI23<=20),CI23+840, IF(AND(J23="S200",CI23>=1,CI23<=20),CI23+200, IF(AND(J23="S100",CI23>=1,CI23<=20),CI23+700, IF(AND(J23="S1000",CI23>=1,CI23<=20),CI23+1000, IF(AND(J23="S400",CI23>=1,CI23<=20),CI23+400, IF(AND(OR(J23="University line",J23="S01"),CI23>=1,CI23<=45),CI23+500, CI23))))))))))))) -> 4 | M23: Phyllastrephus icterinus | N23: 20 | O23: N | P23: B10171 | Q23: [1A]BI10171 | R23: 0 | S23: 0 | T23: 0 | U23: X | W23: N | X23: 4 | Y23: N | Z23: 75 | AB23: 70 | AC23: FAJ | AD23: P | AE23: U | AF23: D | AG23: D | AH23: N | AI23: S | AJ23: S | AM23: 0.59236111 | AO23: 23 | AP23: 1 | AQ23: 16.4 | AR23: 11.2 | AS23: 4 | AT23: 4.3 | AU23: 18.4 | AV23: 9.6 | AW23: 11 | BD23: 1.6146997 | BE23: 10.877583 | CC23: B | CD23: N | CE23: N | CF23: N | CH23: P201-220 | CI23: 4 | CJ23: =IF(COUNTIF(reviewFlags!A:C, A23) > 0, "FLAG", "")
A24: 4600 | B24: 1B | C24: SEM | D24: 0.525 | E24: 16 | F24: 1 | G24: 2024 | H24: =DATE(G24,F24,E24) -> 45307 | I24: Winter_2024 | J24: Cuidad de la Paz (1.613482, 10.882453) | K24: P | L24: =IF(CI24="","", IF(AND(J24="P200W",CI24>=1,CI24<=20),CI24+200, IF(AND(J24="P0E",CI24>=1,CI24<=20),CI24+40, IF(AND(J24="P200E",CI24>=1,CI24<=20),CI24+240, IF(AND(J24="P400W",CI24>=1,CI24<=20),CI24+400, IF(AND(J24="P400E",CI24>=1,CI24<=20),CI24+440, IF(AND(J24="P600E",CI24>=1,CI24<=20),CI24+640, IF(AND(J24="P800E",CI24>=1,CI24<=20),CI24+840, IF(AND(J24="S200",CI24>=1,CI24<=20),CI24+200, IF(AND(J24="S100",CI24>=1,CI24<=20),CI24+700, IF(AND(J24="S1000",CI24>=1,CI24<=20),CI24+1000, IF(AND(J24="S400",CI24>=1,CI24<=20),CI24+400, IF(AND(OR(J24="University line",J24="S01"),CI24>=1,CI24<=45),CI24+500, CI24))))))))))))) -> 15 | M24: Criniger calurus | N24: 33 | O24: N | P24: B11611 | Q24: BI11611 | R24: 0 | S24: 0 | T24: 0 | U24: 3 | W24: NA | X24: 2 | Y24: N | Z24: 92 | AB24: 83 | AC24: FMJ | AD24: P | AE24: U | AF24: D | AG24: N | AH24: N | AI24: N | AJ24: N | AM24: 0.56319444 | AN24: P1-8=N P9=70% 10% S4-6=20% 60% 10% | AQ24: 20.2 | AR24: 13.6 | AS24: 5.4 | AT24: 5.6 | AU24: 20.6 | AV24: 11.8 | AW24: 11.9 | BD24: 1.6150898 | BE24: 10.881696 | CC24: P | CD24: N | CE24: N | CF24: N | CG24: M | CH24: P241-260 | CI24: 15 | CJ24: =IF(COUNTIF(reviewFlags!A:C, A24) > 0, "FLAG", "")
A25: 4601 | B25: 1A | C25: SEM | D25: 0.52916667 | E25: 16 | F25: 1 | G25: 2024 | H25: =DATE(G25,F25,E25) -> 45307 | I25: Winter_2024 | J25: Cuidad de la Paz (1.613482, 10.882453) | K25: P | L25: =IF(CI25="","", IF(AND(J25="P200W",CI25>=1,CI25<=20),CI25+200, IF(AND(J25="P0E",CI25>=1,CI25<=20),CI25+40, IF(AND(J25="P200E",CI25>=1,CI25<=20),CI25+240, IF(AND(J25="P400W",CI25>=1,CI25<=20),CI25+400, IF(AND(J25="P400E",CI25>=1,CI25<=20),CI25+440, IF(AND(J25="P600E",CI25>=1,CI25<=20),CI25+640, IF(AND(J25="P800E",CI25>=1,CI25<=20),CI25+840, IF(AND(J25="S200",CI25>=1,CI25<=20),CI25+200, IF(AND(J25="S100",CI25>=1,CI25<=20),CI25+700, IF(AND(J25="S1000",CI25>=1,CI25<=20),CI25+1000, IF(AND(J25="S400",CI25>=1,CI25<=20),CI25+400, IF(AND(OR(J25="University line",J25="S01"),CI25>=1,CI25<=45),CI25+500, CI25))))))))))))) -> 10 | M25: Criniger ndussumensis | N25: 23 | O25: R | P25: B9920 | Q25: BI9920 | R25: 0 | S25: 0 | T25: 0 | U25: 3 | W25: NA | X25: 3 | Y25: N | Z25: 80 | AB25: 72 | AC25: FMJ | AD25: P | AE25: U | AF25: D | AG25: N | AH25: N | AI25: N | AJ25: S | AM25: 0.57847222 | AN25: P5=70% | AQ25: 18.8 | AR25: 10.4 | AS25: 4.6 | AT25: 5 | AU25: 9.5 | AW25: 11.4 | BD25: 1.6149945 | BE25: 10.881246 | CC25: M | CD25: N | CE25: N | CF25: N | CG25: M | CH25: P241-260 | CI25: 10 | CJ25: =IF(COUNTIF(reviewFlags!A:C, A25) > 0, "FLAG", "")
A26: 4736 | B26: 1D | C26: PCG | D26: 0.31388889 | E26: 16 | F26: 1 | G26: 2024 | H26: =DATE(G26,F26,E26) -> 45307 | I26: Winter_2024 | J26: Cuidad de la Paz (1.613482, 10.882453) | K26: P | L26: =IF(CI26="","", IF(AND(J26="P200W",CI26>=1,CI26<=20),CI26+200, IF(AND(J26="P0E",CI26>=1,CI26<=20),CI26+40, IF(AND(J26="P200E",CI26>=1,CI26<=20),CI26+240, IF(AND(J26="P400W",CI26>=1,CI26<=20),CI26+400, IF(AND(J26="P400E",CI26>=1,CI26<=20),CI26+440, IF(AND(J26="P600E",CI26>=1,CI26<=20),CI26+640, IF(AND(J26="P800E",CI26>=1,CI26<=20),CI26+840, IF(AND(J26="S200",CI26>=1,CI26<=20),CI26+200, IF(AND(J26="S100",CI26>=1,CI26<=20),CI26+700, IF(AND(J26="S1000",CI26>=1,CI26<=20),CI26+1000, IF(AND(J26="S400",CI26>=1,CI26<=20),CI26+400, IF(AND(OR(J26="University line",J26="S01"),CI26>=1,CI26<=45),CI26+500, CI26))))))))))))) -> 11 | M26: Criniger calurus | N26: 32 | O26: N | P26: B10303 | Q26: BI10303 | R26: 0 | S26: 0 | T26: 1 | U26: 3 | W26: S | X26: 1 | Y26: N | Z26: 94 | AB26: 90 | AC26: FMJ | AD26: P | AE26: U | AF26: D | AG26: N | AH26: S | AJ26: N | AM26: 0.34930556 | AN26: P6=60% P7=pin | AQ26: 22.8 | AR26: 14.5 | AS26: 6.1 | AT26: 5.4 | AU26: 22.7 | AW26: 11.8 | BD26: 1.6151117 | BE26: 10.881832 | CC26: R | CD26: N | CE26: N | CF26: R | CG26: M | CH26: P241-260 | CI26: 11 | CJ26: =IF(COUNTIF(reviewFlags!A:C, A26) > 0, "FLAG", "")
A27: 4763 | B27: 1A | C27: BRA | D27: 0.36805556 | E27: 11 | F27: 1 | G27: 2024 | H27: =DATE(G27,F27,E27) -> 45302 | I27: Winter_2024 | J27: Cuidad de la Paz (1.613482, 10.882453) | K27: P | L27: =IF(CI27="","", IF(AND(J27="P200W",CI27>=1,CI27<=20),CI27+200, IF(AND(J27="P0E",CI27>=1,CI27<=20),CI27+40, IF(AND(J27="P200E",CI27>=1,CI27<=20),CI27+240, IF(AND(J27="P400W",CI27>=1,CI27<=20),CI27+400, IF(AND(J27="P400E",CI27>=1,CI27<=20),CI27+440, IF(AND(J27="P600E",CI27>=1,CI27<=20),CI27+640, IF(AND(J27="P800E",CI27>=1,CI27<=20),CI27+840, IF(AND(J27="S200",CI27>=1,CI27<=20),CI27+200, IF(AND(J27="S100",CI27>=1,CI27<=20),CI27+700, IF(AND(J27="S1000",CI27>=1,CI27<=20),CI27+1000, IF(AND(J27="S400",CI27>=1,CI27<=20),CI27+400, IF(AND(OR(J27="University line",J27="S01"),CI27>=1,CI27<=45),CI27+500, CI27))))))))))))) -> 5 | M27: Eurillas latirostris | N27: 27 | O27: N | P27: B10140 | Q27: [1A]BI10140 | R27: 0 | S27: 0 | T27: 1 | U27: 0 | V27: NA | W27: S | X27: X | Y27: N | Z27: 88 | AA27: NA | AB27: 80 | AC27: FMJ | AD27: P | AE27: U | AF27: D | AG27: N | AH27: S | AI27: S | AJ27: N | AM27: 0.38472222 | AN27: S1-2N S3G S4-6V DERECHA S1-2N S3-6V | AQ27: 19.5 | AR27: 19.2 | AS27: 5.6 | AT27: 5.6 | AU27: 19.9 | AV27: 13.9 | AW27: 13.75 | AX27: PG | BD27: 1.6132298 | BE27: 10.878895 | CC27: NA | CD27: N | CE27: N | CF27: R | CG27: N | CH27: P1-20 | CI27: 5 | CJ27: =IF(COUNTIF(reviewFlags!A:C, A27) > 0, "FLAG", "")
A28: 4791 | B28: 1D | C28: PCG | D28: 0.38125 | E28: 19 | F28: 1 | G28: 2024 | H28: =DATE(G28,F28,E28) -> 45310 | I28: Winter_2024 | J28: Cuidad de la Paz (1.613482, 10.882453) | K28: P | L28: =IF(CI28="","", IF(AND(J28="P200W",CI28>=1,CI28<=20),CI28+200, IF(AND(J28="P0E",CI28>=1,CI28<=20),CI28+40, IF(AND(J28="P200E",CI28>=1,CI28<=20),CI28+240, IF(AND(J28="P400W",CI28>=1,CI28<=20),CI28+400, IF(AND(J28="P400E",CI28>=1,CI28<=20),CI28+440, IF(AND(J28="P600E",CI28>=1,CI28<=20),CI28+640, IF(AND(J28="P800E",CI28>=1,CI28<=20),CI28+840, IF(AND(J28="S200",CI28>=1,CI28<=20),CI28+200, IF(AND(J28="S100",CI28>=1,CI28<=20),CI28+700, IF(AND(J28="S1000",CI28>=1,CI28<=20),CI28+1000, IF(AND(J28="S400",CI28>=1,CI28<=20),CI28+400, IF(AND(OR(J28="University line",J28="S01"),CI28>=1,CI28<=45),CI28+500, CI28))))))))))))) -> 1 | M28: Criniger chloronotus | N28: 46.6 | O28: N | P28: B10315 | Q28: BI10315 | R28: 0 | S28: 0 | T28: 1 | U28: 0 | W28: S | X28: 3 | Y28: N | Z28: 105 | AB28: NA | AC28: FMJ | AD28: P | AE28: U | AF28: D | AG28: N | AH28: S | AI28: S | AJ28: N | AM28: 0.42291667 | AN28: P1-4=N P4G=95% P5G=20% P6-10=V S1-2=N S3G=20% S4-6=V | AQ28: 21.5 | AR28: 13.7 | AS28: 5.9 | AT28: 6.7 | AU28: 23.5 | AV28: 17.8 | AW28: 13.9 | BD28: 1.61864 | BE28: 10.882043 | CC28: M | CD28: N | CE28: N | CF28: R | CG28: N | CH28: P641-660 | CI28: 1 | CJ28: =IF(COUNTIF(reviewFlags!A:C, A28) > 0, "FLAG", "")
A29: 4861 | B29: 1B | C29: SEM | D29: 0.49166667 | E29: 16 | F29: 1 | G29: 2024 | H29: =DATE(G29,F29,E29) -> 45307 | I29: Winter_2024 | J29: Cuidad de la Paz (1.613482, 10.882453) | K29: P | L29: =IF(CI29="","", IF(AND(J29="P200W",CI29>=1,CI29<=20),CI29+200, IF(AND(J29="P0E",CI29>=1,CI29<=20),CI29+40, IF(AND(J29="P200E",CI29>=1,CI29<=20),CI29+240, IF(AND(J29="P400W",CI29>=1,CI29<=20),CI29+400, IF(AND(J29="P400E",CI29>=1,CI29<=20),CI29+440, IF(AND(J29="P600E",CI29>=1,CI29<=20),CI29+640, IF(AND(J29="P800E",CI29>=1,CI29<=20),CI29+840, IF(AND(J29="S200",CI29>=1,CI29<=20),CI29+200, IF(AND(J29="S100",CI29>=1,CI29<=20),CI29+700, IF(AND(J29="S1000",CI29>=1,CI29<=20),CI29+1000, IF(AND(J29="S400",CI29>=1,CI29<=20),CI29+400, IF(AND(OR(J29="University line",J29="S01"),CI29>=1,CI29<=45),CI29+500, CI29))))))))))))) -> 3 | M29: Phyllastrephus icterinus | N29: 20 | O29: N | P29: B11608 | Q29: BI11608 | R29: 0 | S29: 0 | T29: 0 | U29: 1 | W29: S | X29: 1 | Y29: N | Z29: 75 | AB29: 68 | AC29: FMJ | AD29: P | AE29: U | AF29: D | AG29: N | AH29: S | AI29: S | AJ29: S | AM29: 0.5125 | AQ29: 16.8 | AR29: 11.5 | AS29: 4.4 | AT29: 4.1 | AU29: 19.3 | AV29: 11.6 | AW29: 11 | BD29: 1.6149945 | BE29: 10.881246 | CC29: R | CD29: N | CE29: N | CF29: N | CG29: R | CH29: P241-260 | CI29: 3 | CJ29: =IF(COUNTIF(reviewFlags!A:C, A29) > 0, "FLAG", "")
A30: 4865 | B30: 1 | C30: SEM | D30: 0.49722222 | E30: 16 | F30: 1 | G30: 2024 | H30: =DATE(G30,F30,E30) -> 45307 | I30: Winter_2024 | J30: Cuidad de la Paz (1.613482, 10.882453) | K30: P | L30: =IF(CI30="","", IF(AND(J30="P200W",CI30>=1,CI30<=20),CI30+200, IF(AND(J30="P0E",CI30>=1,CI30<=20),CI30+40, IF(AND(J30="P200E",CI30>=1,CI30<=20),CI30+240, IF(AND(J30="P400W",CI30>=1,CI30<=20),CI30+400, IF(AND(J30="P400E",CI30>=1,CI30<=20),CI30+440, IF(AND(J30="P600E",CI30>=1,CI30<=20),CI30+640, IF(AND(J30="P800E",CI30>=1,CI30<=20),CI30+840, IF(AND(J30="S200",CI30>=1,CI30<=20),CI30+200, IF(AND(J30="S100",CI30>=1,CI30<=20),CI30+700, IF(AND(J30="S1000",CI30>=1,CI30<=20),CI30+1000, IF(AND(J30="S400",CI30>=1,CI30<=20),CI30+400, IF(AND(OR(J30="University line",J30="S01"),CI30>=1,CI30<=45),CI30+500, CI30))))))))))))) | M30: Phyllastrephus icterinus | N30: 19 | O30: N | P30: B11164 | Q30: BI11164 | R30: 0 | S30: 0 | T30: 0 | U30: 0 | W30: S | X30: 1 | Y30: N | Z30: 65 | AB30: 62 | AC30: FMJ | AD30: P | AE30: U | AF30: D | AG30: N | AH30: S | AI30: S | AJ30: N | AM30: 0.51805556 | AQ30: 15.3 | AR30: 9.6 | AS30: 4.3 | AT30: 3.9 | AU30: 19 | AV30: 8 | AW30: 10.8 | BD30: 1.6149945 | BE30: 10.881246 | CC30: R | CD30: N | CE30: N | CF30: N | CG30: N | CH30: P241-260 | CJ30: =IF(COUNTIF(reviewFlags!A:C, A30) > 0, "FLAG", "")
A31: 4870 | B31: 1 | C31: SEM | D31: 0.50416667 | E31: 28 | F31: 1 | G31: 2024 | H31: =DATE(G31,F31,E31) -> 45319 | I31: Winter_2024 | J31: Cuidad de la Paz (1.613482, 10.882453) | K31: S | L31: =IF(CI31="","", IF(AND(J31="P200W",CI31>=1,CI31<=20),CI31+200, IF(AND(J31="P0E",CI31>=1,CI31<=20),CI31+40, IF(AND(J31="P200E",CI31>=1,CI31<=20),CI31+240, IF(AND(J31="P400W",CI31>=1,CI31<=20),CI31+400, IF(AND(J31="P400E",CI31>=1,CI31<=20),CI31+440, IF(AND(J31="P600E",CI31>=1,CI31<=20),CI31+640, IF(AND(J31="P800E",CI31>=1,CI31<=20),CI31+840, IF(AND(J31="S200",CI31>=1,CI31<=20),CI31+200, IF(AND(J31="S100",CI31>=1,CI31<=20),CI31+700, IF(AND(J31="S1000",CI31>=1,CI31<=20),CI31+1000, IF(AND(J31="S400",CI31>=1,CI31<=20),CI31+400, IF(AND(OR(J31="University line",J31="S01"),CI31>=1,CI31<=45),CI31+500, CI31))))))))))))) -> 3 | M31: Eurillas latirostris | N31: 24 | O31: R | P31: B04521 | Q31: BI04521 | R31: 0 | S31: 0 | T31: 2 | U31: 2 | V31: S | W31: S | X31: 0 | Y31: N | Z31: 78 | AA31: NA | AB31: NA | AC31: FMJ | AD31: P | AE31: U | AF31: D | AG31: N | AH31: N | AI31: N | AJ31: N | AM31: 0.53194444 | AN31: P1-6N,P7G-80%,P8G-0%,S1-2N,S3-20%, | AO31: 8 | AQ31: 21.6 | AR31: 13.2 | AS31: 6.5 | AT31: 6.9 | AU31: 25 | AV31: 5.2 | AW31: 15.3 | BD31: 1.614372 | BE31: 10.861997 | CC31: N | CD31: N | CE31: N | CF31: P | CG31: P | CH31: S1-20 | CI31: 3 | CJ31: =IF(COUNTIF(reviewFlags!A:C, A31) > 0, "FLAG", "")
A32: 5021 | B32: 1A | C32: SAL | D32: 0.52152778 | E32: 13 | F32: 1 | G32: 2024 | H32: =DATE(G32,F32,E32) -> 45304 | I32: Winter_2024 | J32: Cuidad de la Paz (1.613482, 10.882453) | K32: P | L32: =IF(CI32="","", IF(AND(J32="P200W",CI32>=1,CI32<=20),CI32+200, IF(AND(J32="P0E",CI32>=1,CI32<=20),CI32+40, IF(AND(J32="P200E",CI32>=1,CI32<=20),CI32+240, IF(AND(J32="P400W",CI32>=1,CI32<=20),CI32+400, IF(AND(J32="P400E",CI32>=1,CI32<=20),CI32+440, IF(AND(J32="P600E",CI32>=1,CI32<=20),CI32+640, IF(AND(J32="P800E",CI32>=1,CI32<=20),CI32+840, IF(AND(J32="S200",CI32>=1,CI32<=20),CI32+200, IF(AND(J32="S100",CI32>=1,CI32<=20),CI32+700, IF(AND(J32="S1000",CI32>=1,CI32<=20),CI32+1000, IF(AND(J32="S400",CI32>=1,CI32<=20),CI32+400, IF(AND(OR(J32="University line",J32="S01"),CI32>=1,CI32<=45),CI32+500, CI32))))))))))))) | M32: Phyllastrephus icterinus | N32: 21 | O32: N | P32: B10170 | Q32: [1A]BI10170 | R32: 0 | S32: 0 | T32: 0 | U32: 0 | W32: S | X32: 1 | Y32: N | Z32: 75 | AB32: 65 | AC32: FMJ | AD32: P | AE32: U | AF32: D | AG32: N | AH32: N | AI32: S | AJ32: N | AN32: P7G 5%; P6G30%; S5G 30% S4G20% | AO32: 22 | AP32: 2 | AQ32: 16.35 | AR32: 12.4 | AS32: 4.5 | AT32: 5.6 | AU32: 20 | AV32: 10.1 | AW32: 10.7 | BD32: 1.61468 | BE32: 10.877476 | CC32: R | CD32: N | CE32: N | CF32: N | CG32: N | CH32: P201-220 | CJ32: =IF(COUNTIF(reviewFlags!A:C, A32) > 0, "FLAG", "")
A33: 5437 | B33: 1B | C33: CSM | D33: 0.38541667 | E33: 25 | F33: 2 | G33: 2025 | H33: =DATE(G33,F33,E33) -> 45713 | I33: Winter_2025 | J33: Cuidad de la Paz (1.613482, 10.882453) | L33: =IF(CI33="","", IF(AND(J33="P200W",CI33>=1,CI33<=20),CI33+200, IF(AND(J33="P0E",CI33>=1,CI33<=20),CI33+40, IF(AND(J33="P200E",CI33>=1,CI33<=20),CI33+240, IF(AND(J33="P400W",CI33>=1,CI33<=20),CI33+400, IF(AND(J33="P400E",CI33>=1,CI33<=20),CI33+440, IF(AND(J33="P600E",CI33>=1,CI33<=20),CI33+640, IF(AND(J33="P800E",CI33>=1,CI33<=20),CI33+840, IF(AND(J33="S200",CI33>=1,CI33<=20),CI33+200, IF(AND(J33="S100",CI33>=1,CI33<=20),CI33+700, IF(AND(J33="S1000",CI33>=1,CI33<=20),CI33+1000, IF(AND(J33="S400",CI33>=1,CI33<=20),CI33+400, IF(AND(OR(J33="University line",J33="S01"),CI33>=1,CI33<=45),CI33+500, CI33))))))))))))) -> 11 | M33: Eurillas latirostris | N33: 21.8 | O33: R | P33: B05073 | Q33: BI05073 | R33: 0 | S33: 0 | T33: 0 | U33: 0 | W33: N | X33: 1 | Y33: N | Z33: 78 | AB33: 79 | AC33: FAJ | AD33: P | AE33: U | AF33: D | AG33: N | AM33: 0.39375 | AQ33: 15 | AR33: 9.2 | AT33: 5 | AU33: 19.5 | AV33: 13 | AW33: 12.3 | CC33: R | CD33: N | CE33: N | CF33: N | CG33: N | CH33: PL1 | CI33: 11 | CJ33: =IF(COUNTIF(reviewFlags!A:C, A33) > 0, "FLAG", "")
A34: 5455 | B34: 2.8 mm | C34: CSM | D34: 0.41041667 | E34: 25 | F34: 2 | G34: 2025 | H34: =DATE(G34,F34,E34) -> 45713 | I34: Winter_2025 | J34: Cuidad de la Paz (1.613482, 10.882453) | L34: =IF(CI34="","", IF(AND(J34="P200W",CI34>=1,CI34<=20),CI34+200, IF(AND(J34="P0E",CI34>=1,CI34<=20),CI34+40, IF(AND(J34="P200E",CI34>=1,CI34<=20),CI34+240, IF(AND(J34="P400W",CI34>=1,CI34<=20),CI34+400, IF(AND(J34="P400E",CI34>=1,CI34<=20),CI34+440, IF(AND(J34="P600E",CI34>=1,CI34<=20),CI34+640, IF(AND(J34="P800E",CI34>=1,CI34<=20),CI34+840, IF(AND(J34="S200",CI34>=1,CI34<=20),CI34+200, IF(AND(J34="S100",CI34>=1,CI34<=20),CI34+700, IF(AND(J34="S1000",CI34>=1,CI34<=20),CI34+1000, IF(AND(J34="S400",CI34>=1,CI34<=20),CI34+400, IF(AND(OR(J34="University line",J34="S01"),CI34>=1,CI34<=45),CI34+500, CI34))))))))))))) -> 20 | M34: Eurillas latirostris | N34: 21.8 | O34: N | P34: FC76518 | Q34: FC76518 | R34: 0 | S34: 1 | T34: 1 | U34: 0 | W34: N | X34: 1 | Y34: N | Z34: 80 | AB34: 74 | AC34: FAJ | AD34: P | AE34: U | AF34: D | AG34: N | AM34: 0.42222222 | AQ34: 12.9 | AR34: 91 | AT34: 4.9 | AU34: 20 | AV34: 11.8 | AW34: 13.2 | BJ34: 82 | CC34: R | CD34: N | CE34: L | CF34: R | CG34: N | CH34: PL1 | CI34: 20 | CJ34: =IF(COUNTIF(reviewFlags!A:C, A34) > 0, "FLAG", "")
A35: 5460 | B35: 2.8 mm | C35: PN | D35: 0.41180556 | E35: 28 | F35: 2 | G35: 2025 | H35: =DATE(G35,F35,E35) -> 45716 | I35: Winter_2025 | J35: Cuidad de la Paz (1.613482, 10.882453) | K35: S | L35: =IF(CI35="","", IF(AND(J35="P200W",CI35>=1,CI35<=20),CI35+200, IF(AND(J35="P0E",CI35>=1,CI35<=20),CI35+40, IF(AND(J35="P200E",CI35>=1,CI35<=20),CI35+240, IF(AND(J35="P400W",CI35>=1,CI35<=20),CI35+400, IF(AND(J35="P400E",CI35>=1,CI35<=20),CI35+440, IF(AND(J35="P600E",CI35>=1,CI35<=20),CI35+640, IF(AND(J35="P800E",CI35>=1,CI35<=20),CI35+840, IF(AND(J35="S200",CI35>=1,CI35<=20),CI35+200, IF(AND(J35="S100",CI35>=1,CI35<=20),CI35+700, IF(AND(J35="S1000",CI35>=1,CI35<=20),CI35+1000, IF(AND(J35="S400",CI35>=1,CI35<=20),CI35+400, IF(AND(OR(J35="University line",J35="S01"),CI35>=1,CI35<=45),CI35+500, CI35))))))))))))) -> OBI-1 | M35: Eurillas latirostris | N35: 30 | O35: N | P35: FC76535 | Q35: FC76535 | R35: 0 | S35: 0 | T35: 1 | U35: 4 | W35: N | X35: 1 | Y35: N | Z35: 83 | AB35: 78 | AC35: FAJ | AD35: P | AE35: U | AF35: D | AG35: N | AM35: 0.43125 | AQ35: 15.3 | AR35: 10.4 | AS35: 5.9 | AT35: 4.9 | AU35: 15.9 | AV35: 13 | AW35: 10.9 | BJ35: 85 | CC35: R | CD35: N | CE35: N | CF35: R | CG35: B | CH35: S1021-1040 | CI35: OBI-1 | CJ35: =IF(COUNTIF(reviewFlags!A:C, A35) > 0, "FLAG", "")
A36: 5487 | B36: 1B | C36: PN | D36: 0.45625 | E36: 25 | F36: 2 | G36: 2025 | H36: =DATE(G36,F36,E36) -> 45713 | I36: Winter_2025 | J36: Cuidad de la Paz (1.613482, 10.882453) | L36: =IF(CI36="","", IF(AND(J36="P200W",CI36>=1,CI36<=20),CI36+200, IF(AND(J36="P0E",CI36>=1,CI36<=20),CI36+40, IF(AND(J36="P200E",CI36>=1,CI36<=20),CI36+240, IF(AND(J36="P400W",CI36>=1,CI36<=20),CI36+400, IF(AND(J36="P400E",CI36>=1,CI36<=20),CI36+440, IF(AND(J36="P600E",CI36>=1,CI36<=20),CI36+640, IF(AND(J36="P800E",CI36>=1,CI36<=20),CI36+840, IF(AND(J36="S200",CI36>=1,CI36<=20),CI36+200, IF(AND(J36="S100",CI36>=1,CI36<=20),CI36+700, IF(AND(J36="S1000",CI36>=1,CI36<=20),CI36+1000, IF(AND(J36="S400",CI36>=1,CI36<=20),CI36+400, IF(AND(OR(J36="University line",J36="S01"),CI36>=1,CI36<=45),CI36+500, CI36))))))))))))) -> 14 | M36: Eurillas latirostris | N36: 23.9 | O36: R | P36: B11539 | Q36: BI11539 | R36: 0 | S36: 2 | T36: 1 | U36: 0 | W36: N | X36: 1 | Y36: N | Z36: 81 | AB36: 75 | AC36: FAJ | AD36: P | AE36: U | AF36: D | AG36: N | AM36: 0.46597222 | AQ36: 14 | AR36: 10.3 | AS36: 4.8 | AT36: 4.2 | AU36: 20.8 | AV36: 14.9 | AW36: 12.8 | CC36: R | CD36: N | CE36: V | CF36: R | CG36: N | CH36: PL1 | CI36: 14 | CJ36: =IF(COUNTIF(reviewFlags!A:C, A36) > 0, "FLAG", "")
A37: 5513 | B37: 2.8 mm | C37: PN | D37: 0.48680556 | E37: 25 | F37: 2 | G37: 2025 | H37: =DATE(G37,F37,E37) -> 45713 | I37: Winter_2025 | J37: Cuidad de la Paz (1.613482, 10.882453) | L37: =IF(CI37="","", IF(AND(J37="P200W",CI37>=1,CI37<=20),CI37+200, IF(AND(J37="P0E",CI37>=1,CI37<=20),CI37+40, IF(AND(J37="P200E",CI37>=1,CI37<=20),CI37+240, IF(AND(J37="P400W",CI37>=1,CI37<=20),CI37+400, IF(AND(J37="P400E",CI37>=1,CI37<=20),CI37+440, IF(AND(J37="P600E",CI37>=1,CI37<=20),CI37+640, IF(AND(J37="P800E",CI37>=1,CI37<=20),CI37+840, IF(AND(J37="S200",CI37>=1,CI37<=20),CI37+200, IF(AND(J37="S100",CI37>=1,CI37<=20),CI37+700, IF(AND(J37="S1000",CI37>=1,CI37<=20),CI37+1000, IF(AND(J37="S400",CI37>=1,CI37<=20),CI37+400, IF(AND(OR(J37="University line",J37="S01"),CI37>=1,CI37<=45),CI37+500, CI37))))))))))))) -> 600G | M37: Eurillas latirostris | N37: NA | O37: N | P37: FC76519 | Q37: FC76519 | R37: 0 | S37: 1 | T37: 1 | U37: 1 | W37: N | X37: 3 | Y37: N | Z37: 80 | AB37: 74 | AC37: FAJ | AD37: P | AE37: U | AF37: D | AG37: N | AM37: 0.50625 | AQ37: 14.9 | AR37: 8.5 | AS37: 4.1 | AT37: 4.5 | AU37: 20.1 | AV37: 12.1 | AW37: 12.6 | BJ37: 83 | CC37: M | CD37: N | CE37: L | CF37: R | CG37: R | CH37: PL1 | CI37: 600G | CJ37: =IF(COUNTIF(reviewFlags!A:C, A37) > 0, "FLAG", "")
A38: 5515 | B38: 1B | C38: CSM | D38: 0.48611111 | E38: 25 | F38: 2 | G38: 2025 | H38: =DATE(G38,F38,E38) -> 45713 | I38: Winter_2025 | J38: Cuidad de la Paz (1.613482, 10.882453) | L38: =IF(CI38="","", IF(AND(J38="P200W",CI38>=1,CI38<=20),CI38+200, IF(AND(J38="P0E",CI38>=1,CI38<=20),CI38+40, IF(AND(J38="P200E",CI38>=1,CI38<=20),CI38+240, IF(AND(J38="P400W",CI38>=1,CI38<=20),CI38+400, IF(AND(J38="P400E",CI38>=1,CI38<=20),CI38+440, IF(AND(J38="P600E",CI38>=1,CI38<=20),CI38+640, IF(AND(J38="P800E",CI38>=1,CI38<=20),CI38+840, IF(AND(J38="S200",CI38>=1,CI38<=20),CI38+200, IF(AND(J38="S100",CI38>=1,CI38<=20),CI38+700, IF(AND(J38="S1000",CI38>=1,CI38<=20),CI38+1000, IF(AND(J38="S400",CI38>=1,CI38<=20),CI38+400, IF(AND(OR(J38="University line",J38="S01"),CI38>=1,CI38<=45),CI38+500, CI38))))))))))))) -> OBI-1 | M38: Eurillas latirostris | N38: 23.7 | O38: R | P38: B10176 | Q38: [1B]BI10176 | R38: 0 | S38: 0 | T38: 1 | U38: 0 | W38: N | X38: 1 | Y38: N | Z38: 80 | AB38: 76 | AC38: FAJ | AD38: P | AE38: U | AF38: D | AG38: N | AM38: 0.51180556 | AQ38: 13 | AR38: 9 | AS38: 4.3 | AT38: 4.9 | AU38: 18.5 | AV38: 12.5 | AW38: 11.8 | CC38: R | CD38: N | CE38: N | CF38: R | CG38: N | CH38: PL1 | CI38: OBI-1 | CJ38: =IF(COUNTIF(reviewFlags!A:C, A38) > 0, "FLAG", "")
A39: 5687 | B39: 2.8 mm | C39: R | D39: 0.33819444 | E39: 4 | F39: 3 | G39: 2025 | H39: =DATE(G39,F39,E39) -> 45720 | I39: Winter_2025 | J39: Cuidad de la Paz (1.613482, 10.882453) | L39: =IF(CI39="","", IF(AND(J39="P200W",CI39>=1,CI39<=20),CI39+200, IF(AND(J39="P0E",CI39>=1,CI39<=20),CI39+40, IF(AND(J39="P200E",CI39>=1,CI39<=20),CI39+240, IF(AND(J39="P400W",CI39>=1,CI39<=20),CI39+400, IF(AND(J39="P400E",CI39>=1,CI39<=20),CI39+440, IF(AND(J39="P600E",CI39>=1,CI39<=20),CI39+640, IF(AND(J39="P800E",CI39>=1,CI39<=20),CI39+840, IF(AND(J39="S200",CI39>=1,CI39<=20),CI39+200, IF(AND(J39="S100",CI39>=1,CI39<=20),CI39+700, IF(AND(J39="S1000",CI39>=1,CI39<=20),CI39+1000, IF(AND(J39="S400",CI39>=1,CI39<=20),CI39+400, IF(AND(OR(J39="University line",J39="S01"),CI39>=1,CI39<=45),CI39+500, CI39))))))))))))) -> No_Red | M39: Eurillas latirostris | N39: 27.2 | O39: N | P39: FC76662 | Q39: FC76662 | R39: 0 | S39: 0 | T39: 0 | U39: 0 | W39: N | X39: 1 | Y39: N | Z39: 83 | AB39: 75 | AC39: MFCF | AD39: P | AE39: U | AG39: N | AH39: N | AI39: N | AJ39: N | AO39: 4 | AQ39: 16.8 | AR39: 10 | AS39: 4 | AT39: 4.8 | AU39: 21.6 | AV39: 27.2 | AW39: 11.5 | BJ39: 86 | BN39: N | BP39: SAFRING | CB39: N | CC39: 1 | CD39: 0 | CE39: 0 | CF39: 0 | CG39: 0 | CH39: DN | CI39: No_Red | CJ39: =IF(COUNTIF(reviewFlags!A:C, A39) > 0, "FLAG", "")
A40: 5688 | B40: 2.8 mm | C40: N | D40: 0.33819444 | E40: 4 | F40: 3 | G40: 2025 | H40: =DATE(G40,F40,E40) -> 45720 | I40: Winter_2025 | J40: Cuidad de la Paz (1.613482, 10.882453) | L40: =IF(CI40="","", IF(AND(J40="P200W",CI40>=1,CI40<=20),CI40+200, IF(AND(J40="P0E",CI40>=1,CI40<=20),CI40+40, IF(AND(J40="P200E",CI40>=1,CI40<=20),CI40+240, IF(AND(J40="P400W",CI40>=1,CI40<=20),CI40+400, IF(AND(J40="P400E",CI40>=1,CI40<=20),CI40+440, IF(AND(J40="P600E",CI40>=1,CI40<=20),CI40+640, IF(AND(J40="P800E",CI40>=1,CI40<=20),CI40+840, IF(AND(J40="S200",CI40>=1,CI40<=20),CI40+200, IF(AND(J40="S100",CI40>=1,CI40<=20),CI40+700, IF(AND(J40="S1000",CI40>=1,CI40<=20),CI40+1000, IF(AND(J40="S400",CI40>=1,CI40<=20),CI40+400, IF(AND(OR(J40="University line",J40="S01"),CI40>=1,CI40<=45),CI40+500, CI40))))))))))))) -> 8 | M40: Eurillas latirostris | N40: 22.2 | O40: N | P40: FC76663 | Q40: FC76663 | R40: 0 | S40: 4 | T40: 0 | U40: 0 | W40: N | X40: 1 | Y40: N | Z40: 77 | AB40: 71 | AC40: MFCF | AD40: P | AE40: U | AG40: N | AH40: N | AI40: N | AJ40: N | AO40: 5 | AQ40: 14.3 | AR40: 9.3 | AS40: 5.1 | AT40: 4.6 | AU40: 20 | AV40: 12 | AW40: 10.8 | BJ40: 79 | BN40: N | BP40: SAFRING | CB40: N | CC40: 1 | CD40: 0 | CE40: 4 | CF40: 0 | CG40: 0 | CH40: DN | CI40: 8 | CJ40: =IF(COUNTIF(reviewFlags!A:C, A40) > 0, "FLAG", "")
...

Sheet Metadata
A1: ENG | B1: ESP | C1: New Field Value | D1: New Field Value Details (Eng) | E1: Old Field Value Equivalent | F1: Old Field Value Details (Esp) | G1: Notes
A2: New/Recap | B2: Nuevo.Recap | C2: N | D2: New | E2: N | F2: Nuevo
C3: R | D3: Recap | E3: R | F3: Recaptura
C4: S | D4: Same day recapture | E4: S
A5: Fat score | B5: Grasa | C5: 0 | D5: No fat anywhere | E5: N
C6: 1 | D6: Furcular hollow less than 5% full. | E6: R,T
C7: 2 | D7: Furcular hollow 5-33% full. | E7: C,P,L
C8: 3 | D8: Furcular hollow about half full (34%-66%). | E8: M
C9: 4 | D9: Furcular hollow full, 67%-100%, fat thick in wingpits and on abdomen. | E9: H,LL
C10: 5 | D10: Fat bulging above furcular hollow, in wingpits, and on abdomen. | E10: X
C11: 6 | D11: Fat greatly bulging in all areas.
C12: 7 | D12: Excessive; fat nearly joined from all areas.
C13: X | D13: Not assessed
A14: Pec score | B14: Musculo | C14: 0 | D14: None
C15: 1 | D15: Breast is very concave; no discernable muscle mass around keel
C16: 2 | D16: Muscle mass is concave; bird is somewhat keeled
C17: 3 | D17: Muscle mass extends down and out from keel but surface is flat (pyramid shape)
C18: 4 | D18: Muscle mass is rounded/convex but not fully rounded, can still see keel
C19: 5 | D19: Muscle mass is fully rounded (no keel)
C20: X | D20: Not assessed
A21: Brood patch | B21: Placa.de.Incubacion | C21: 0 | D21: None present, breast feathered. | E21: N | F21: No hay
C22: 1 | D22: Feathers dropped, skin smooth and dark red; some vascularization. | E22: L,S | F22: Piel lisa
C23: 2 | D23: Skin vascularized and wrinkled, fluid present. | E23: V | F23: Vascularizado
C24: 3 | D24: Vascularization extreme, skin wrinkled, much fluid. | E24: F | F24: Muy fluido
C25: 4 | D25: Wrinkled skin, thin and dry; vascularization and fluid mostly gone. | E25: A,W | F25: Arrugado
C26: 5 | D26: Vascularization, fluid, and wrinkles gone; pinfeathers appearing. | E26: M | F26: En muda
C27: J | D27: "Baby belly". Exposed flesh on the belly of some juvenile birds. | E27: J | F27: Parche falso
C28: X | D28: Not assessed
A29: Cloacal protuberance | B29: Cloaca | C29: 0 | D29: Cloaca not enlarged. | E29: N | F29: No hay
C30: 1 | D30: Small (conical; wide at base, narrow at tip.) | E30: P,S | F30: Pequeño
C31: 2 | D31: Medium (cylindrical; as large at tip as at base.) | E31: M | F31: Mediana
C32: 3 | D32: Large (bulbous; larger at tip than at base.) | E32: G,L | F32: Grande
C33: X | D33: Not assessed
A34: Skull pneumatization | B34: Craneo | C34: 0 | D34: None; single pinkish layer.
C35: 1 | D35: Trace at very back of skull; 1-5% of total area.
C36: 2 | D36: 6-33% at back; distinct contrast; whitish dots.
C37: 3 | D37: 34-66%; rear half and some of front, midline, and sides.
C38: 4 | D38: 67-94%; two oval red spots either side of cranium - rest completed.
C39: 5 | D39: 95-99%; two tiny pinkish spots. (Some birds stay at class 5.)
C40: 6 | D40: Complete, fully pneumaticized.
...

Sheet Band number calculator
A1: record_number | B1: Numero.de.Anillo | C1: OYALA / NSORK / BIOKO | D1: band_num_est (V2) | E1: prefix V2 | F1: concat_dupl | G1: band_num_est (special) | H1: corrected num only | I1: corrected "special" prefix | J1: band_num_est (actual) | K1: corrected "actual" prefix | L1: original prefix | M1: original number sans | N1: band_num_est_details
A2: 3209 | B2: ??? | C2: OYALA | D2: NO BAND | G2: NO BAND | H2: {=_xlfn.TEXTJOIN("",,MID(G2,MIN(SEARCH({0,1,2,3,4,5,6,7,8,9},G2&"0123456789")),99))} | I2: NO BAND | J2: NO BAND | M2: NO BAND | N2: No band
A3: 3475 | B3: B10010 | C3: OYALA | D3: =E3&H3 -> BI10010 | E3: BI | G3: =$I3&$M3 -> [1A]BI10010 | H3: {=_xlfn.TEXTJOIN("",,MID(J3,MIN(SEARCH({0,1,2,3,4,5,6,7,8,9},J3&"0123456789")),99))} -> 10010 | I3: [1A]BI | J3: =K3&M3 -> BI10010 | K3: BI | L3: B | M3: 10010 | N3: Nums 10101-10200 size 1A w/ “[1A]BI” prefix deployed as "N" from Winter_2019 until Winter_2024 to distinguish w/ overlapping string of 1B rings.
A4: 1005 | B4: 3620 | C4: OYALA | D4: =E4&H4 -> BI03620 | E4: BI | F4: =captureData!#REF!&"_"&D4 -> #REF! | G4: =$I4&$M4 -> BI03620 | H4: {=_xlfn.TEXTJOIN("",,MID(G4,MIN(SEARCH({0,1,2,3,4,5,6,7,8,9},G4&"0123456789")),99))} -> 03620 | I4: BI0 | J4: =K4&M4 -> BI03620 | K4: BI0 | M4: 3620 | N4: Nums 3601-4000 size 0A w/ “BI0” prefix (no overlap with other strings)
A5: 1658 | B5: 3621 | C5: OYALA | G5: =$I5&$M5 -> BI03621 | H5: {=_xlfn.TEXTJOIN("",,MID(G5,MIN(SEARCH({0,1,2,3,4,5,6,7,8,9},G5&"0123456789")),99))} -> 03621 | I5: BI0 | J5: =K5&M5 -> BI03621 | K5: BI0 | M5: 3621 | N5: Nums 3601-4000 size 0A w/ “BI0” prefix (no overlap with other strings)
A6: 713 | B6: 21 | C6: OYALA | D6: =E6&H6 -> EGBI00021 | E6: EGBI | F6: =captureData!#REF!&"_"&D6 -> #REF! | G6: =$I6&$M6 -> EGBI00021 | H6: {=_xlfn.TEXTJOIN("",,MID(G6,MIN(SEARCH({0,1,2,3,4,5,6,7,8,9},G6&"0123456789")),99))} -> 00021 | I6: EGBI | J6: =K6&M6 -> EGBI00021 | K6: EGBI | M6: 00021 | N6: Nums 0001-1500 deployed BEFORE Winter_2023 ASSUMED w/ "EGBI0” prefix
A7: 631 | B7: 517 | C7: BIOKO | D7: =E7&H7 -> EGBI00517 | E7: EGBI | F7: =captureData!#REF!&"_"&D7 -> #REF! | G7: =$I7&$M7 -> EGBI00517 | H7: {=_xlfn.TEXTJOIN("",,MID(G7,MIN(SEARCH({0,1,2,3,4,5,6,7,8,9},G7&"0123456789")),99))} -> 00517 | I7: EGBI00 | J7: =K7&M7 -> EGBI00517 | K7: EGBI00 | M7: 517 | N7: Nums 0001-1500 deployed BEFORE Winter_2023 ASSUMED w/ "EGBI0” prefix
A8: 4416 | B8: B10104 | C8: OYALA | G8: =$I8&$M8 -> [1A]BI10104 | H8: {=_xlfn.TEXTJOIN("",,MID(J8,MIN(SEARCH({0,1,2,3,4,5,6,7,8,9},J8&"0123456789")),99))} -> 10104 | I8: [1A]BI | J8: =K8&M8 -> BI10104 | K8: BI | L8: B | M8: 10104 | N8: Nums 10101-10200 size 1A w/ “[1A]BI” prefix deployed as "N" from Winter_2019 until Winter_2024 to distinguish w/ overlapping string of 1B rings.
A9: 574 | B9: 521 | C9: BIOKO | D9: =E9&H9 -> EGBI00521 | E9: EGBI | F9: =captureData!#REF!&"_"&D9 -> #REF! | G9: =$I9&$M9 -> EGBI00521 | H9: {=_xlfn.TEXTJOIN("",,MID(G9,MIN(SEARCH({0,1,2,3,4,5,6,7,8,9},G9&"0123456789")),99))} -> 00521 | I9: EGBI00 | J9: =K9&M9 -> EGBI00521 | K9: EGBI00 | M9: 521 | N9: Nums 0001-1500 deployed BEFORE Winter_2023 ASSUMED w/ "EGBI0” prefix
A10: 4970 | B10: B10105 | C10: OYALA | G10: =$I10&$M10 -> [1A]BI10105 | H10: {=_xlfn.TEXTJOIN("",,MID(J10,MIN(SEARCH({0,1,2,3,4,5,6,7,8,9},J10&"0123456789")),99))} -> 10105 | I10: [1A]BI | J10: =K10&M10 -> BI10105 | K10: BI | L10: B | M10: 10105 | N10: Nums 10101-10200 size 1A w/ “[1A]BI” prefix deployed as "N" from Winter_2019 until Winter_2024 to distinguish w/ overlapping string of 1B rings.
